Workbook

Sheet Xulosa
A1: Aros — admin panel uchun regression test-keyslar
A2: Admin panel, UI. Confluence dagi PRD va staging-admin bilan solishtirilgan (28.10.2026). Vitrina — alohida fayl.
A4: Muhit | B4: https://staging-admin.aros.uz (til: O'zbekcha)
A5: Rol | B5: Administrator (to'liq huquqlar)
A6: Test akkaunti | B6: Login: +998998987882 Parol: <пароль в .env> в .env>
A7: Hujjatlar | B7: Confluence → admin panel mantiqi papkasi; havolalar «Manbalar» varag'ida
A8: Avtotestlar | B8: aros-ui repozitoriyasi: Java 21 + Playwright + JUnit5 + Allure
A9: Reliz / versiya | J9: ← sariq maydonlar har bir progondan oldin to'ldiriladi
A10: Progon sanasi
A11: Testchi
A12: Modullar bo'yicha qamrov
A13: Modul | B13: Jami | C13: P1 | D13: P2 | E13: P3 | F13: Avto mumkin: Ha | G13: Qisman | H13: Yo'q | I13: Avtomatlashtirilgan | J13: Avtotestlar qamrovi % | K13: Passed | L13: Failed | M13: Blocked | N13: Skipped | O13: Bajarilmagan
A14: AUTH — Avtorizatsiya va ruxsat | B14: =COUNTIF('Test-keyslar'!$B$2:$B$167,"Avtorizatsiya va ruxsat") | C14: =COUNTIFS('Test-keyslar'!$B$2:$B$167,"Avtorizatsiya va ruxsat",'Test-keyslar'!$E$2:$E$167,"P1") | D14: =COUNTIFS('Test-keyslar'!$B$2:$B$167,"Avtorizatsiya va ruxsat",'Test-keyslar'!$E$2:$E$167,"P2") | E14: =COUNTIFS('Test-keyslar'!$B$2:$B$167,"Avtorizatsiya va ruxsat",'Test-keyslar'!$E$2:$E$167,"P3") | F14: =COUNTIFS('Test-keyslar'!$B$2:$B$167,"Avtorizatsiya va ruxsat",'Test-keyslar'!$L$2:$L$167,"Ha") | G14: =COUNTIFS('Test-keyslar'!$B$2:$B$167,"Avtorizatsiya va ruxsat",'Test-keyslar'!$L$2:$L$167,"Qisman") | H14: =COUNTIFS('Test-keyslar'!$B$2:$B$167,"Avtorizatsiya va ruxsat",'Test-keyslar'!$L$2:$L$167,"Yo'q") | I14: =COUNTIFS('Test-keyslar'!$B$2:$B$167,"Avtorizatsiya va ruxsat",'Test-keyslar'!$N$2:$N$167,"Avtomatlashtirilgan") | J14: =IF(B14=0,0,I14/B14) | K14: =COUNTIFS('Test-keyslar'!$B$2:$B$167,"Avtorizatsiya va ruxsat",'Test-keyslar'!$P$2:$P$167,"Passed") | L14: =COUNTIFS('Test-keyslar'!$B$2:$B$167,"Avtorizatsiya va ruxsat",'Test-keyslar'!$P$2:$P$167,"Failed") | M14: =COUNTIFS('Test-keyslar'!$B$2:$B$167,"Avtorizatsiya va ruxsat",'Test-keyslar'!$P$2:$P$167,"Blocked") | N14: =COUNTIFS('Test-keyslar'!$B$2:$B$167,"Avtorizatsiya va ruxsat",'Test-keyslar'!$P$2:$P$167,"Skipped") | O14: =COUNTIFS('Test-keyslar'!$B$2:$B$167,"Avtorizatsiya va ruxsat",'Test-keyslar'!$P$2:$P$167,"Bajarilmagan")
A15: DASH — Bosh sahifa (Dashboard) | B15: =COUNTIF('Test-keyslar'!$B$2:$B$167,"Bosh sahifa (Dashboard)") | C15: =COUNTIFS('Test-keyslar'!$B$2:$B$167,"Bosh sahifa (Dashboard)",'Test-keyslar'!$E$2:$E$167,"P1") | D15: =COUNTIFS('Test-keyslar'!$B$2:$B$167,"Bosh sahifa (Dashboard)",'Test-keyslar'!$E$2:$E$167,"P2") | E15: =COUNTIFS('Test-keyslar'!$B$2:$B$167,"Bosh sahifa (Dashboard)",'Test-keyslar'!$E$2:$E$167,"P3") | F15: =COUNTIFS('Test-keyslar'!$B$2:$B$167,"Bosh sahifa (Dashboard)",'Test-keyslar'!$L$2:$L$167,"Ha") | G15: =COUNTIFS('Test-keyslar'!$B$2:$B$167,"Bosh sahifa (Dashboard)",'Test-keyslar'!$L$2:$L$167,"Qisman") | H15: =COUNTIFS('Test-keyslar'!$B$2:$B$167,"Bosh sahifa (Dashboard)",'Test-keyslar'!$L$2:$L$167,"Yo'q") | I15: =COUNTIFS('Test-keyslar'!$B$2:$B$167,"Bosh sahifa (Dashboard)",'Test-keyslar'!$N$2:$N$167,"Avtomatlashtirilgan") | J15: =IF(B15=0,0,I15/B15) | K15: =COUNTIFS('Test-keyslar'!$B$2:$B$167,"Bosh sahifa (Dashboard)",'Test-keyslar'!$P$2:$P$167,"Passed") | L15: =COUNTIFS('Test-keyslar'!$B$2:$B$167,"Bosh sahifa (Dashboard)",'Test-keyslar'!$P$2:$P$167,"Failed") | M15: =COUNTIFS('Test-keyslar'!$B$2:$B$167,"Bosh sahifa (Dashboard)",'Test-keyslar'!$P$2:$P$167,"Blocked") | N15: =COUNTIFS('Test-keyslar'!$B$2:$B$167,"Bosh sahifa (Dashboard)",'Test-keyslar'!$P$2:$P$167,"Skipped") | O15: =COUNTIFS('Test-keyslar'!$B$2:$B$167,"Bosh sahifa (Dashboard)",'Test-keyslar'!$P$2:$P$167,"Bajarilmagan")
A16: PINC — Qabul qilingan mahsulot (kirim) | B16: =COUNTIF('Test-keyslar'!$B$2:$B$167,"Qabul qilingan mahsulot (kirim)") | C16: =COUNTIFS('Test-keyslar'!$B$2:$B$167,"Qabul qilingan mahsulot (kirim)",'Test-keyslar'!$E$2:$E$167,"P1") | D16: =COUNTIFS('Test-keyslar'!$B$2:$B$167,"Qabul qilingan mahsulot (kirim)",'Test-keyslar'!$E$2:$E$167,"P2") | E16: =COUNTIFS('Test-keyslar'!$B$2:$B$167,"Qabul qilingan mahsulot (kirim)",'Test-keyslar'!$E$2:$E$167,"P3") | F16: =COUNTIFS('Test-keyslar'!$B$2:$B$167,"Qabul qilingan mahsulot (kirim)",'Test-keyslar'!$L$2:$L$167,"Ha") | G16: =COUNTIFS('Test-keyslar'!$B$2:$B$167,"Qabul qilingan mahsulot (kirim)",'Test-keyslar'!$L$2:$L$167,"Qisman") | H16: =COUNTIFS('Test-keyslar'!$B$2:$B$167,"Qabul qilingan mahsulot (kirim)",'Test-keyslar'!$L$2:$L$167,"Yo'q") | I16: =COUNTIFS('Test-keyslar'!$B$2:$B$167,"Qabul qilingan mahsulot (kirim)",'Test-keyslar'!$N$2:$N$167,"Avtomatlashtirilgan") | J16: =IF(B16=0,0,I16/B16) | K16: =COUNTIFS('Test-keyslar'!$B$2:$B$167,"Qabul qilingan mahsulot (kirim)",'Test-keyslar'!$P$2:$P$167,"Passed") | L16: =COUNTIFS('Test-keyslar'!$B$2:$B$167,"Qabul qilingan mahsulot (kirim)",'Test-keyslar'!$P$2:$P$167,"Failed") | M16: =COUNTIFS('Test-keyslar'!$B$2:$B$167,"Qabul qilingan mahsulot (kirim)",'Test-keyslar'!$P$2:$P$167,"Blocked") | N16: =COUNTIFS('Test-keyslar'!$B$2:$B$167,"Qabul qilingan mahsulot (kirim)",'Test-keyslar'!$P$2:$P$167,"Skipped") | O16: =COUNTIFS('Test-keyslar'!$B$2:$B$167,"Qabul qilingan mahsulot (kirim)",'Test-keyslar'!$P$2:$P$167,"Bajarilmagan")
A17: PRICE — Narxni o'zgartirish | B17: =COUNTIF('Test-keyslar'!$B$2:$B$167,"Narxni o'zgartirish") | C17: =COUNTIFS('Test-keyslar'!$B$2:$B$167,"Narxni o'zgartirish",'Test-keyslar'!$E$2:$E$167,"P1") | D17: =COUNTIFS('Test-keyslar'!$B$2:$B$167,"Narxni o'zgartirish",'Test-keyslar'!$E$2:$E$167,"P2") | E17: =COUNTIFS('Test-keyslar'!$B$2:$B$167,"Narxni o'zgartirish",'Test-keyslar'!$E$2:$E$167,"P3") | F17: =COUNTIFS('Test-keyslar'!$B$2:$B$167,"Narxni o'zgartirish",'Test-keyslar'!$L$2:$L$167,"Ha") | G17: =COUNTIFS('Test-keyslar'!$B$2:$B$167,"Narxni o'zgartirish",'Test-keyslar'!$L$2:$L$167,"Qisman") | H17: =COUNTIFS('Test-keyslar'!$B$2:$B$167,"Narxni o'zgartirish",'Test-keyslar'!$L$2:$L$167,"Yo'q") | I17: =COUNTIFS('Test-keyslar'!$B$2:$B$167,"Narxni o'zgartirish",'Test-keyslar'!$N$2:$N$167,"Avtomatlashtirilgan") | J17: =IF(B17=0,0,I17/B17) | K17: =COUNTIFS('Test-keyslar'!$B$2:$B$167,"Narxni o'zgartirish",'Test-keyslar'!$P$2:$P$167,"Passed") | L17: =COUNTIFS('Test-keyslar'!$B$2:$B$167,"Narxni o'zgartirish",'Test-keyslar'!$P$2:$P$167,"Failed") | M17: =COUNTIFS('Test-keyslar'!$B$2:$B$167,"Narxni o'zgartirish",'Test-keyslar'!$P$2:$P$167,"Blocked") | N17: =COUNTIFS('Test-keyslar'!$B$2:$B$167,"Narxni o'zgartirish",'Test-keyslar'!$P$2:$P$167,"Skipped") | O17: =COUNTIFS('Test-keyslar'!$B$2:$B$167,"Narxni o'zgartirish",'Test-keyslar'!$P$2:$P$167,"Bajarilmagan")
A18: INV — Inventarizatsiya | B18: =COUNTIF('Test-keyslar'!$B$2:$B$167,"Inventarizatsiya") | C18: =COUNTIFS('Test-keyslar'!$B$2:$B$167,"Inventarizatsiya",'Test-keyslar'!$E$2:$E$167,"P1") | D18: =COUNTIFS('Test-keyslar'!$B$2:$B$167,"Inventarizatsiya",'Test-keyslar'!$E$2:$E$167,"P2") | E18: =COUNTIFS('Test-keyslar'!$B$2:$B$167,"Inventarizatsiya",'Test-keyslar'!$E$2:$E$167,"P3") | F18: =COUNTIFS('Test-keyslar'!$B$2:$B$167,"Inventarizatsiya",'Test-keyslar'!$L$2:$L$167,"Ha") | G18: =COUNTIFS('Test-keyslar'!$B$2:$B$167,"Inventarizatsiya",'Test-keyslar'!$L$2:$L$167,"Qisman") | H18: =COUNTIFS('Test-keyslar'!$B$2:$B$167,"Inventarizatsiya",'Test-keyslar'!$L$2:$L$167,"Yo'q") | I18: =COUNTIFS('Test-keyslar'!$B$2:$B$167,"Inventarizatsiya",'Test-keyslar'!$N$2:$N$167,"Avtomatlashtirilgan") | J18: =IF(B18=0,0,I18/B18) | K18: =COUNTIFS('Test-keyslar'!$B$2:$B$167,"Inventarizatsiya",'Test-keyslar'!$P$2:$P$167,"Passed") | L18: =COUNTIFS('Test-keyslar'!$B$2:$B$167,"Inventarizatsiya",'Test-keyslar'!$P$2:$P$167,"Failed") | M18: =COUNTIFS('Test-keyslar'!$B$2:$B$167,"Inventarizatsiya",'Test-keyslar'!$P$2:$P$167,"Blocked") | N18: =COUNTIFS('Test-keyslar'!$B$2:$B$167,"Inventarizatsiya",'Test-keyslar'!$P$2:$P$167,"Skipped") | O18: =COUNTIFS('Test-keyslar'!$B$2:$B$167,"Inventarizatsiya",'Test-keyslar'!$P$2:$P$167,"Bajarilmagan")
A19: TRF — Mahsulot yuborish (o'tkazma) | B19: =COUNTIF('Test-keyslar'!$B$2:$B$167,"Mahsulot yuborish (o'tkazma)") | C19: =COUNTIFS('Test-keyslar'!$B$2:$B$167,"Mahsulot yuborish (o'tkazma)",'Test-keyslar'!$E$2:$E$167,"P1") | D19: =COUNTIFS('Test-keyslar'!$B$2:$B$167,"Mahsulot yuborish (o'tkazma)",'Test-keyslar'!$E$2:$E$167,"P2") | E19: =COUNTIFS('Test-keyslar'!$B$2:$B$167,"Mahsulot yuborish (o'tkazma)",'Test-keyslar'!$E$2:$E$167,"P3") | F19: =COUNTIFS('Test-keyslar'!$B$2:$B$167,"Mahsulot yuborish (o'tkazma)",'Test-keyslar'!$L$2:$L$167,"Ha") | G19: =COUNTIFS('Test-keyslar'!$B$2:$B$167,"Mahsulot yuborish (o'tkazma)",'Test-keyslar'!$L$2:$L$167,"Qisman") | H19: =COUNTIFS('Test-keyslar'!$B$2:$B$167,"Mahsulot yuborish (o'tkazma)",'Test-keyslar'!$L$2:$L$167,"Yo'q") | I19: =COUNTIFS('Test-keyslar'!$B$2:$B$167,"Mahsulot yuborish (o'tkazma)",'Test-keyslar'!$N$2:$N$167,"Avtomatlashtirilgan") | J19: =IF(B19=0,0,I19/B19) | K19: =COUNTIFS('Test-keyslar'!$B$2:$B$167,"Mahsulot yuborish (o'tkazma)",'Test-keyslar'!$P$2:$P$167,"Passed") | L19: =COUNTIFS('Test-keyslar'!$B$2:$B$167,"Mahsulot yuborish (o'tkazma)",'Test-keyslar'!$P$2:$P$167,"Failed") | M19: =COUNTIFS('Test-keyslar'!$B$2:$B$167,"Mahsulot yuborish (o'tkazma)",'Test-keyslar'!$P$2:$P$167,"Blocked") | N19: =COUNTIFS('Test-keyslar'!$B$2:$B$167,"Mahsulot yuborish (o'tkazma)",'Test-keyslar'!$P$2:$P$167,"Skipped") | O19: =COUNTIFS('Test-keyslar'!$B$2:$B$167,"Mahsulot yuborish (o'tkazma)",'Test-keyslar'!$P$2:$P$167,"Bajarilmagan")
A20: PVAR — Mahsulot varianti (ehtiyoj) | B20: =COUNTIF('Test-keyslar'!$B$2:$B$167,"Mahsulot varianti (ehtiyoj)") | C20: =COUNTIFS('Test-keyslar'!$B$2:$B$167,"Mahsulot varianti (ehtiyoj)",'Test-keyslar'!$E$2:$E$167,"P1") | D20: =COUNTIFS('Test-keyslar'!$B$2:$B$167,"Mahsulot varianti (ehtiyoj)",'Test-keyslar'!$E$2:$E$167,"P2") | E20: =COUNTIFS('Test-keyslar'!$B$2:$B$167,"Mahsulot varianti (ehtiyoj)",'Test-keyslar'!$E$2:$E$167,"P3") | F20: =COUNTIFS('Test-keyslar'!$B$2:$B$167,"Mahsulot varianti (ehtiyoj)",'Test-keyslar'!$L$2:$L$167,"Ha") | G20: =COUNTIFS('Test-keyslar'!$B$2:$B$167,"Mahsulot varianti (ehtiyoj)",'Test-keyslar'!$L$2:$L$167,"Qisman") | H20: =COUNTIFS('Test-keyslar'!$B$2:$B$167,"Mahsulot varianti (ehtiyoj)",'Test-keyslar'!$L$2:$L$167,"Yo'q") | I20: =COUNTIFS('Test-keyslar'!$B$2:$B$167,"Mahsulot varianti (ehtiyoj)",'Test-keyslar'!$N$2:$N$167,"Avtomatlashtirilgan") | J20: =IF(B20=0,0,I20/B20) | K20: =COUNTIFS('Test-keyslar'!$B$2:$B$167,"Mahsulot varianti (ehtiyoj)",'Test-keyslar'!$P$2:$P$167,"Passed") | L20: =COUNTIFS('Test-keyslar'!$B$2:$B$167,"Mahsulot varianti (ehtiyoj)",'Test-keyslar'!$P$2:$P$167,"Failed") | M20: =COUNTIFS('Test-keyslar'!$B$2:$B$167,"Mahsulot varianti (ehtiyoj)",'Test-keyslar'!$P$2:$P$167,"Blocked") | N20: =COUNTIFS('Test-keyslar'!$B$2:$B$167,"Mahsulot varianti (ehtiyoj)",'Test-keyslar'!$P$2:$P$167,"Skipped") | O20: =COUNTIFS('Test-keyslar'!$B$2:$B$167,"Mahsulot varianti (ehtiyoj)",'Test-keyslar'!$P$2:$P$167,"Bajarilmagan")
A21: DISC — Chegirma va aksiyalar | B21: =COUNTIF('Test-keyslar'!$B$2:$B$167,"Chegirma va aksiyalar") | C21: =COUNTIFS('Test-keyslar'!$B$2:$B$167,"Chegirma va aksiyalar",'Test-keyslar'!$E$2:$E$167,"P1") | D21: =COUNTIFS('Test-keyslar'!$B$2:$B$167,"Chegirma va aksiyalar",'Test-keyslar'!$E$2:$E$167,"P2") | E21: =COUNTIFS('Test-keyslar'!$B$2:$B$167,"Chegirma va aksiyalar",'Test-keyslar'!$E$2:$E$167,"P3") | F21: =COUNTIFS('Test-keyslar'!$B$2:$B$167,"Chegirma va aksiyalar",'Test-keyslar'!$L$2:$L$167,"Ha") | G21: =COUNTIFS('Test-keyslar'!$B$2:$B$167,"Chegirma va aksiyalar",'Test-keyslar'!$L$2:$L$167,"Qisman") | H21: =COUNTIFS('Test-keyslar'!$B$2:$B$167,"Chegirma va aksiyalar",'Test-keyslar'!$L$2:$L$167,"Yo'q") | I21: =COUNTIFS('Test-keyslar'!$B$2:$B$167,"Chegirma va aksiyalar",'Test-keyslar'!$N$2:$N$167,"Avtomatlashtirilgan") | J21: =IF(B21=0,0,I21/B21) | K21: =COUNTIFS('Test-keyslar'!$B$2:$B$167,"Chegirma va aksiyalar",'Test-keyslar'!$P$2:$P$167,"Passed") | L21: =COUNTIFS('Test-keyslar'!$B$2:$B$167,"Chegirma va aksiyalar",'Test-keyslar'!$P$2:$P$167,"Failed") | M21: =COUNTIFS('Test-keyslar'!$B$2:$B$167,"Chegirma va aksiyalar",'Test-keyslar'!$P$2:$P$167,"Blocked") | N21: =COUNTIFS('Test-keyslar'!$B$2:$B$167,"Chegirma va aksiyalar",'Test-keyslar'!$P$2:$P$167,"Skipped") | O21: =COUNTIFS('Test-keyslar'!$B$2:$B$167,"Chegirma va aksiyalar",'Test-keyslar'!$P$2:$P$167,"Bajarilmagan")
A22: PROD — Mahsulotlar va variantlar | B22: =COUNTIF('Test-keyslar'!$B$2:$B$167,"Mahsulotlar va variantlar") | C22: =COUNTIFS('Test-keyslar'!$B$2:$B$167,"Mahsulotlar va variantlar",'Test-keyslar'!$E$2:$E$167,"P1") | D22: =COUNTIFS('Test-keyslar'!$B$2:$B$167,"Mahsulotlar va variantlar",'Test-keyslar'!$E$2:$E$167,"P2") | E22: =COUNTIFS('Test-keyslar'!$B$2:$B$167,"Mahsulotlar va variantlar",'Test-keyslar'!$E$2:$E$167,"P3") | F22: =COUNTIFS('Test-keyslar'!$B$2:$B$167,"Mahsulotlar va variantlar",'Test-keyslar'!$L$2:$L$167,"Ha") | G22: =COUNTIFS('Test-keyslar'!$B$2:$B$167,"Mahsulotlar va variantlar",'Test-keyslar'!$L$2:$L$167,"Qisman") | H22: =COUNTIFS('Test-keyslar'!$B$2:$B$167,"Mahsulotlar va variantlar",'Test-keyslar'!$L$2:$L$167,"Yo'q") | I22: =COUNTIFS('Test-keyslar'!$B$2:$B$167,"Mahsulotlar va variantlar",'Test-keyslar'!$N$2:$N$167,"Avtomatlashtirilgan") | J22: =IF(B22=0,0,I22/B22) | K22: =COUNTIFS('Test-keyslar'!$B$2:$B$167,"Mahsulotlar va variantlar",'Test-keyslar'!$P$2:$P$167,"Passed") | L22: =COUNTIFS('Test-keyslar'!$B$2:$B$167,"Mahsulotlar va variantlar",'Test-keyslar'!$P$2:$P$167,"Failed") | M22: =COUNTIFS('Test-keyslar'!$B$2:$B$167,"Mahsulotlar va variantlar",'Test-keyslar'!$P$2:$P$167,"Blocked") | N22: =COUNTIFS('Test-keyslar'!$B$2:$B$167,"Mahsulotlar va variantlar",'Test-keyslar'!$P$2:$P$167,"Skipped") | O22: =COUNTIFS('Test-keyslar'!$B$2:$B$167,"Mahsulotlar va variantlar",'Test-keyslar'!$P$2:$P$167,"Bajarilmagan")
A23: DIR — Katalog ma'lumotnomalari | B23: =COUNTIF('Test-keyslar'!$B$2:$B$167,"Katalog ma'lumotnomalari") | C23: =COUNTIFS('Test-keyslar'!$B$2:$B$167,"Katalog ma'lumotnomalari",'Test-keyslar'!$E$2:$E$167,"P1") | D23: =COUNTIFS('Test-keyslar'!$B$2:$B$167,"Katalog ma'lumotnomalari",'Test-keyslar'!$E$2:$E$167,"P2") | E23: =COUNTIFS('Test-keyslar'!$B$2:$B$167,"Katalog ma'lumotnomalari",'Test-keyslar'!$E$2:$E$167,"P3") | F23: =COUNTIFS('Test-keyslar'!$B$2:$B$167,"Katalog ma'lumotnomalari",'Test-keyslar'!$L$2:$L$167,"Ha") | G23: =COUNTIFS('Test-keyslar'!$B$2:$B$167,"Katalog ma'lumotnomalari",'Test-keyslar'!$L$2:$L$167,"Qisman") | H23: =COUNTIFS('Test-keyslar'!$B$2:$B$167,"Katalog ma'lumotnomalari",'Test-keyslar'!$L$2:$L$167,"Yo'q") | I23: =COUNTIFS('Test-keyslar'!$B$2:$B$167,"Katalog ma'lumotnomalari",'Test-keyslar'!$N$2:$N$167,"Avtomatlashtirilgan") | J23: =IF(B23=0,0,I23/B23) | K23: =COUNTIFS('Test-keyslar'!$B$2:$B$167,"Katalog ma'lumotnomalari",'Test-keyslar'!$P$2:$P$167,"Passed") | L23: =COUNTIFS('Test-keyslar'!$B$2:$B$167,"Katalog ma'lumotnomalari",'Test-keyslar'!$P$2:$P$167,"Failed") | M23: =COUNTIFS('Test-keyslar'!$B$2:$B$167,"Katalog ma'lumotnomalari",'Test-keyslar'!$P$2:$P$167,"Blocked") | N23: =COUNTIFS('Test-keyslar'!$B$2:$B$167,"Katalog ma'lumotnomalari",'Test-keyslar'!$P$2:$P$167,"Skipped") | O23: =COUNTIFS('Test-keyslar'!$B$2:$B$167,"Katalog ma'lumotnomalari",'Test-keyslar'!$P$2:$P$167,"Bajarilmagan")
A24: ORD — Buyurtmalar | B24: =COUNTIF('Test-keyslar'!$B$2:$B$167,"Buyurtmalar") | C24: =COUNTIFS('Test-keyslar'!$B$2:$B$167,"Buyurtmalar",'Test-keyslar'!$E$2:$E$167,"P1") | D24: =COUNTIFS('Test-keyslar'!$B$2:$B$167,"Buyurtmalar",'Test-keyslar'!$E$2:$E$167,"P2") | E24: =COUNTIFS('Test-keyslar'!$B$2:$B$167,"Buyurtmalar",'Test-keyslar'!$E$2:$E$167,"P3") | F24: =COUNTIFS('Test-keyslar'!$B$2:$B$167,"Buyurtmalar",'Test-keyslar'!$L$2:$L$167,"Ha") | G24: =COUNTIFS('Test-keyslar'!$B$2:$B$167,"Buyurtmalar",'Test-keyslar'!$L$2:$L$167,"Qisman") | H24: =COUNTIFS('Test-keyslar'!$B$2:$B$167,"Buyurtmalar",'Test-keyslar'!$L$2:$L$167,"Yo'q") | I24: =COUNTIFS('Test-keyslar'!$B$2:$B$167,"Buyurtmalar",'Test-keyslar'!$N$2:$N$167,"Avtomatlashtirilgan") | J24: =IF(B24=0,0,I24/B24) | K24: =COUNTIFS('Test-keyslar'!$B$2:$B$167,"Buyurtmalar",'Test-keyslar'!$P$2:$P$167,"Passed") | L24: =COUNTIFS('Test-keyslar'!$B$2:$B$167,"Buyurtmalar",'Test-keyslar'!$P$2:$P$167,"Failed") | M24: =COUNTIFS('Test-keyslar'!$B$2:$B$167,"Buyurtmalar",'Test-keyslar'!$P$2:$P$167,"Blocked") | N24: =COUNTIFS('Test-keyslar'!$B$2:$B$167,"Buyurtmalar",'Test-keyslar'!$P$2:$P$167,"Skipped") | O24: =COUNTIFS('Test-keyslar'!$B$2:$B$167,"Buyurtmalar",'Test-keyslar'!$P$2:$P$167,"Bajarilmagan")
A25: SW — Sotuv oynasi | B25: =COUNTIF('Test-keyslar'!$B$2:$B$167,"Sotuv oynasi") | C25: =COUNTIFS('Test-keyslar'!$B$2:$B$167,"Sotuv oynasi",'Test-keyslar'!$E$2:$E$167,"P1") | D25: =COUNTIFS('Test-keyslar'!$B$2:$B$167,"Sotuv oynasi",'Test-keyslar'!$E$2:$E$167,"P2") | E25: =COUNTIFS('Test-keyslar'!$B$2:$B$167,"Sotuv oynasi",'Test-keyslar'!$E$2:$E$167,"P3") | F25: =COUNTIFS('Test-keyslar'!$B$2:$B$167,"Sotuv oynasi",'Test-keyslar'!$L$2:$L$167,"Ha") | G25: =COUNTIFS('Test-keyslar'!$B$2:$B$167,"Sotuv oynasi",'Test-keyslar'!$L$2:$L$167,"Qisman") | H25: =COUNTIFS('Test-keyslar'!$B$2:$B$167,"Sotuv oynasi",'Test-keyslar'!$L$2:$L$167,"Yo'q") | I25: =COUNTIFS('Test-keyslar'!$B$2:$B$167,"Sotuv oynasi",'Test-keyslar'!$N$2:$N$167,"Avtomatlashtirilgan") | J25: =IF(B25=0,0,I25/B25) | K25: =COUNTIFS('Test-keyslar'!$B$2:$B$167,"Sotuv oynasi",'Test-keyslar'!$P$2:$P$167,"Passed") | L25: =COUNTIFS('Test-keyslar'!$B$2:$B$167,"Sotuv oynasi",'Test-keyslar'!$P$2:$P$167,"Failed") | M25: =COUNTIFS('Test-keyslar'!$B$2:$B$167,"Sotuv oynasi",'Test-keyslar'!$P$2:$P$167,"Blocked") | N25: =COUNTIFS('Test-keyslar'!$B$2:$B$167,"Sotuv oynasi",'Test-keyslar'!$P$2:$P$167,"Skipped") | O25: =COUNTIFS('Test-keyslar'!$B$2:$B$167,"Sotuv oynasi",'Test-keyslar'!$P$2:$P$167,"Bajarilmagan")
A26: RET — Mahsulot qaytarish | B26: =COUNTIF('Test-keyslar'!$B$2:$B$167,"Mahsulot qaytarish") | C26: =COUNTIFS('Test-keyslar'!$B$2:$B$167,"Mahsulot qaytarish",'Test-keyslar'!$E$2:$E$167,"P1") | D26: =COUNTIFS('Test-keyslar'!$B$2:$B$167,"Mahsulot qaytarish",'Test-keyslar'!$E$2:$E$167,"P2") | E26: =COUNTIFS('Test-keyslar'!$B$2:$B$167,"Mahsulot qaytarish",'Test-keyslar'!$E$2:$E$167,"P3") | F26: =COUNTIFS('Test-keyslar'!$B$2:$B$167,"Mahsulot qaytarish",'Test-keyslar'!$L$2:$L$167,"Ha") | G26: =COUNTIFS('Test-keyslar'!$B$2:$B$167,"Mahsulot qaytarish",'Test-keyslar'!$L$2:$L$167,"Qisman") | H26: =COUNTIFS('Test-keyslar'!$B$2:$B$167,"Mahsulot qaytarish",'Test-keyslar'!$L$2:$L$167,"Yo'q") | I26: =COUNTIFS('Test-keyslar'!$B$2:$B$167,"Mahsulot qaytarish",'Test-keyslar'!$N$2:$N$167,"Avtomatlashtirilgan") | J26: =IF(B26=0,0,I26/B26) | K26: =COUNTIFS('Test-keyslar'!$B$2:$B$167,"Mahsulot qaytarish",'Test-keyslar'!$P$2:$P$167,"Passed") | L26: =COUNTIFS('Test-keyslar'!$B$2:$B$167,"Mahsulot qaytarish",'Test-keyslar'!$P$2:$P$167,"Failed") | M26: =COUNTIFS('Test-keyslar'!$B$2:$B$167,"Mahsulot qaytarish",'Test-keyslar'!$P$2:$P$167,"Blocked") | N26: =COUNTIFS('Test-keyslar'!$B$2:$B$167,"Mahsulot qaytarish",'Test-keyslar'!$P$2:$P$167,"Skipped") | O26: =COUNTIFS('Test-keyslar'!$B$2:$B$167,"Mahsulot qaytarish",'Test-keyslar'!$P$2:$P$167,"Bajarilmagan")
A27: BIL — Hisob-kitob (kassa) | B27: =COUNTIF('Test-keyslar'!$B$2:$B$167,"Hisob-kitob (kassa)") | C27: =COUNTIFS('Test-keyslar'!$B$2:$B$167,"Hisob-kitob (kassa)",'Test-keyslar'!$E$2:$E$167,"P1") | D27: =COUNTIFS('Test-keyslar'!$B$2:$B$167,"Hisob-kitob (kassa)",'Test-keyslar'!$E$2:$E$167,"P2") | E27: =COUNTIFS('Test-keyslar'!$B$2:$B$167,"Hisob-kitob (kassa)",'Test-keyslar'!$E$2:$E$167,"P3") | F27: =COUNTIFS('Test-keyslar'!$B$2:$B$167,"Hisob-kitob (kassa)",'Test-keyslar'!$L$2:$L$167,"Ha") | G27: =COUNTIFS('Test-keyslar'!$B$2:$B$167,"Hisob-kitob (kassa)",'Test-keyslar'!$L$2:$L$167,"Qisman") | H27: =COUNTIFS('Test-keyslar'!$B$2:$B$167,"Hisob-kitob (kassa)",'Test-keyslar'!$L$2:$L$167,"Yo'q") | I27: =COUNTIFS('Test-keyslar'!$B$2:$B$167,"Hisob-kitob (kassa)",'Test-keyslar'!$N$2:$N$167,"Avtomatlashtirilgan") | J27: =IF(B27=0,0,I27/B27) | K27: =COUNTIFS('Test-keyslar'!$B$2:$B$167,"Hisob-kitob (kassa)",'Test-keyslar'!$P$2:$P$167,"Passed") | L27: =COUNTIFS('Test-keyslar'!$B$2:$B$167,"Hisob-kitob (kassa)",'Test-keyslar'!$P$2:$P$167,"Failed") | M27: =COUNTIFS('Test-keyslar'!$B$2:$B$167,"Hisob-kitob (kassa)",'Test-keyslar'!$P$2:$P$167,"Blocked") | N27: =COUNTIFS('Test-keyslar'!$B$2:$B$167,"Hisob-kitob (kassa)",'Test-keyslar'!$P$2:$P$167,"Skipped") | O27: =COUNTIFS('Test-keyslar'!$B$2:$B$167,"Hisob-kitob (kassa)",'Test-keyslar'!$P$2:$P$167,"Bajarilmagan")
A28: USR — Foydalanuvchilar va mijoz rollari | B28: =COUNTIF('Test-keyslar'!$B$2:$B$167,"Foydalanuvchilar va mijoz rollari") | C28: =COUNTIFS('Test-keyslar'!$B$2:$B$167,"Foydalanuvchilar va mijoz rollari",'Test-keyslar'!$E$2:$E$167,"P1") | D28: =COUNTIFS('Test-keyslar'!$B$2:$B$167,"Foydalanuvchilar va mijoz rollari",'Test-keyslar'!$E$2:$E$167,"P2") | E28: =COUNTIFS('Test-keyslar'!$B$2:$B$167,"Foydalanuvchilar va mijoz rollari",'Test-keyslar'!$E$2:$E$167,"P3") | F28: =COUNTIFS('Test-keyslar'!$B$2:$B$167,"Foydalanuvchilar va mijoz rollari",'Test-keyslar'!$L$2:$L$167,"Ha") | G28: =COUNTIFS('Test-keyslar'!$B$2:$B$167,"Foydalanuvchilar va mijoz rollari",'Test-keyslar'!$L$2:$L$167,"Qisman") | H28: =COUNTIFS('Test-keyslar'!$B$2:$B$167,"Foydalanuvchilar va mijoz rollari",'Test-keyslar'!$L$2:$L$167,"Yo'q") | I28: =COUNTIFS('Test-keyslar'!$B$2:$B$167,"Foydalanuvchilar va mijoz rollari",'Test-keyslar'!$N$2:$N$167,"Avtomatlashtirilgan") | J28: =IF(B28=0,0,I28/B28) | K28: =COUNTIFS('Test-keyslar'!$B$2:$B$167,"Foydalanuvchilar va mijoz rollari",'Test-keyslar'!$P$2:$P$167,"Passed") | L28: =COUNTIFS('Test-keyslar'!$B$2:$B$167,"Foydalanuvchilar va mijoz rollari",'Test-keyslar'!$P$2:$P$167,"Failed") | M28: =COUNTIFS('Test-keyslar'!$B$2:$B$167,"Foydalanuvchilar va mijoz rollari",'Test-keyslar'!$P$2:$P$167,"Blocked") | N28: =COUNTIFS('Test-keyslar'!$B$2:$B$167,"Foydalanuvchilar va mijoz rollari",'Test-keyslar'!$P$2:$P$167,"Skipped") | O28: =COUNTIFS('Test-keyslar'!$B$2:$B$167,"Foydalanuvchilar va mijoz rollari",'Test-keyslar'!$P$2:$P$167,"Bajarilmagan")
A29: REQ — Mijoz so'rovlari | B29: =COUNTIF('Test-keyslar'!$B$2:$B$167,"Mijoz so'rovlari") | C29: =COUNTIFS('Test-keyslar'!$B$2:$B$167,"Mijoz so'rovlari",'Test-keyslar'!$E$2:$E$167,"P1") | D29: =COUNTIFS('Test-keyslar'!$B$2:$B$167,"Mijoz so'rovlari",'Test-keyslar'!$E$2:$E$167,"P2") | E29: =COUNTIFS('Test-keyslar'!$B$2:$B$167,"Mijoz so'rovlari",'Test-keyslar'!$E$2:$E$167,"P3") | F29: =COUNTIFS('Test-keyslar'!$B$2:$B$167,"Mijoz so'rovlari",'Test-keyslar'!$L$2:$L$167,"Ha") | G29: =COUNTIFS('Test-keyslar'!$B$2:$B$167,"Mijoz so'rovlari",'Test-keyslar'!$L$2:$L$167,"Qisman") | H29: =COUNTIFS('Test-keyslar'!$B$2:$B$167,"Mijoz so'rovlari",'Test-keyslar'!$L$2:$L$167,"Yo'q") | I29: =COUNTIFS('Test-keyslar'!$B$2:$B$167,"Mijoz so'rovlari",'Test-keyslar'!$N$2:$N$167,"Avtomatlashtirilgan") | J29: =IF(B29=0,0,I29/B29) | K29: =COUNTIFS('Test-keyslar'!$B$2:$B$167,"Mijoz so'rovlari",'Test-keyslar'!$P$2:$P$167,"Passed") | L29: =COUNTIFS('Test-keyslar'!$B$2:$B$167,"Mijoz so'rovlari",'Test-keyslar'!$P$2:$P$167,"Failed") | M29: =COUNTIFS('Test-keyslar'!$B$2:$B$167,"Mijoz so'rovlari",'Test-keyslar'!$P$2:$P$167,"Blocked") | N29: =COUNTIFS('Test-keyslar'!$B$2:$B$167,"Mijoz so'rovlari",'Test-keyslar'!$P$2:$P$167,"Skipped") | O29: =COUNTIFS('Test-keyslar'!$B$2:$B$167,"Mijoz so'rovlari",'Test-keyslar'!$P$2:$P$167,"Bajarilmagan")
A30: WH — Omborlar | B30: =COUNTIF('Test-keyslar'!$B$2:$B$167,"Omborlar") | C30: =COUNTIFS('Test-keyslar'!$B$2:$B$167,"Omborlar",'Test-keyslar'!$E$2:$E$167,"P1") | D30: =COUNTIFS('Test-keyslar'!$B$2:$B$167,"Omborlar",'Test-keyslar'!$E$2:$E$167,"P2") | E30: =COUNTIFS('Test-keyslar'!$B$2:$B$167,"Omborlar",'Test-keyslar'!$E$2:$E$167,"P3") | F30: =COUNTIFS('Test-keyslar'!$B$2:$B$167,"Omborlar",'Test-keyslar'!$L$2:$L$167,"Ha") | G30: =COUNTIFS('Test-keyslar'!$B$2:$B$167,"Omborlar",'Test-keyslar'!$L$2:$L$167,"Qisman") | H30: =COUNTIFS('Test-keyslar'!$B$2:$B$167,"Omborlar",'Test-keyslar'!$L$2:$L$167,"Yo'q") | I30: =COUNTIFS('Test-keyslar'!$B$2:$B$167,"Omborlar",'Test-keyslar'!$N$2:$N$167,"Avtomatlashtirilgan") | J30: =IF(B30=0,0,I30/B30) | K30: =COUNTIFS('Test-keyslar'!$B$2:$B$167,"Omborlar",'Test-keyslar'!$P$2:$P$167,"Passed") | L30: =COUNTIFS('Test-keyslar'!$B$2:$B$167,"Omborlar",'Test-keyslar'!$P$2:$P$167,"Failed") | M30: =COUNTIFS('Test-keyslar'!$B$2:$B$167,"Omborlar",'Test-keyslar'!$P$2:$P$167,"Blocked") | N30: =COUNTIFS('Test-keyslar'!$B$2:$B$167,"Omborlar",'Test-keyslar'!$P$2:$P$167,"Skipped") | O30: =COUNTIFS('Test-keyslar'!$B$2:$B$167,"Omborlar",'Test-keyslar'!$P$2:$P$167,"Bajarilmagan")
A31: CUR — Valyuta | B31: =COUNTIF('Test-keyslar'!$B$2:$B$167,"Valyuta") | C31: =COUNTIFS('Test-keyslar'!$B$2:$B$167,"Valyuta",'Test-keyslar'!$E$2:$E$167,"P1") | D31: =COUNTIFS('Test-keyslar'!$B$2:$B$167,"Valyuta",'Test-keyslar'!$E$2:$E$167,"P2") | E31: =COUNTIFS('Test-keyslar'!$B$2:$B$167,"Valyuta",'Test-keyslar'!$E$2:$E$167,"P3") | F31: =COUNTIFS('Test-keyslar'!$B$2:$B$167,"Valyuta",'Test-keyslar'!$L$2:$L$167,"Ha") | G31: =COUNTIFS('Test-keyslar'!$B$2:$B$167,"Valyuta",'Test-keyslar'!$L$2:$L$167,"Qisman") | H31: =COUNTIFS('Test-keyslar'!$B$2:$B$167,"Valyuta",'Test-keyslar'!$L$2:$L$167,"Yo'q") | I31: =COUNTIFS('Test-keyslar'!$B$2:$B$167,"Valyuta",'Test-keyslar'!$N$2:$N$167,"Avtomatlashtirilgan") | J31: =IF(B31=0,0,I31/B31) | K31: =COUNTIFS('Test-keyslar'!$B$2:$B$167,"Valyuta",'Test-keyslar'!$P$2:$P$167,"Passed") | L31: =COUNTIFS('Test-keyslar'!$B$2:$B$167,"Valyuta",'Test-keyslar'!$P$2:$P$167,"Failed") | M31: =COUNTIFS('Test-keyslar'!$B$2:$B$167,"Valyuta",'Test-keyslar'!$P$2:$P$167,"Blocked") | N31: =COUNTIFS('Test-keyslar'!$B$2:$B$167,"Valyuta",'Test-keyslar'!$P$2:$P$167,"Skipped") | O31: =COUNTIFS('Test-keyslar'!$B$2:$B$167,"Valyuta",'Test-keyslar'!$P$2:$P$167,"Bajarilmagan")
A32: BAN — Bannerlar | B32: =COUNTIF('Test-keyslar'!$B$2:$B$167,"Bannerlar") | C32: =COUNTIFS('Test-keyslar'!$B$2:$B$167,"Bannerlar",'Test-keyslar'!$E$2:$E$167,"P1") | D32: =COUNTIFS('Test-keyslar'!$B$2:$B$167,"Bannerlar",'Test-keyslar'!$E$2:$E$167,"P2") | E32: =COUNTIFS('Test-keyslar'!$B$2:$B$167,"Bannerlar",'Test-keyslar'!$E$2:$E$167,"P3") | F32: =COUNTIFS('Test-keyslar'!$B$2:$B$167,"Bannerlar",'Test-keyslar'!$L$2:$L$167,"Ha") | G32: =COUNTIFS('Test-keyslar'!$B$2:$B$167,"Bannerlar",'Test-keyslar'!$L$2:$L$167,"Qisman") | H32: =COUNTIFS('Test-keyslar'!$B$2:$B$167,"Bannerlar",'Test-keyslar'!$L$2:$L$167,"Yo'q") | I32: =COUNTIFS('Test-keyslar'!$B$2:$B$167,"Bannerlar",'Test-keyslar'!$N$2:$N$167,"Avtomatlashtirilgan") | J32: =IF(B32=0,0,I32/B32) | K32: =COUNTIFS('Test-keyslar'!$B$2:$B$167,"Bannerlar",'Test-keyslar'!$P$2:$P$167,"Passed") | L32: =COUNTIFS('Test-keyslar'!$B$2:$B$167,"Bannerlar",'Test-keyslar'!$P$2:$P$167,"Failed") | M32: =COUNTIFS('Test-keyslar'!$B$2:$B$167,"Bannerlar",'Test-keyslar'!$P$2:$P$167,"Blocked") | N32: =COUNTIFS('Test-keyslar'!$B$2:$B$167,"Bannerlar",'Test-keyslar'!$P$2:$P$167,"Skipped") | O32: =COUNTIFS('Test-keyslar'!$B$2:$B$167,"Bannerlar",'Test-keyslar'!$P$2:$P$167,"Bajarilmagan")
A33: DEBT — Qarz va hamyon | B33: =COUNTIF('Test-keyslar'!$B$2:$B$167,"Qarz va hamyon") | C33: =COUNTIFS('Test-keyslar'!$B$2:$B$167,"Qarz va hamyon",'Test-keyslar'!$E$2:$E$167,"P1") | D33: =COUNTIFS('Test-keyslar'!$B$2:$B$167,"Qarz va hamyon",'Test-keyslar'!$E$2:$E$167,"P2") | E33: =COUNTIFS('Test-keyslar'!$B$2:$B$167,"Qarz va hamyon",'Test-keyslar'!$E$2:$E$167,"P3") | F33: =COUNTIFS('Test-keyslar'!$B$2:$B$167,"Qarz va hamyon",'Test-keyslar'!$L$2:$L$167,"Ha") | G33: =COUNTIFS('Test-keyslar'!$B$2:$B$167,"Qarz va hamyon",'Test-keyslar'!$L$2:$L$167,"Qisman") | H33: =COUNTIFS('Test-keyslar'!$B$2:$B$167,"Qarz va hamyon",'Test-keyslar'!$L$2:$L$167,"Yo'q") | I33: =COUNTIFS('Test-keyslar'!$B$2:$B$167,"Qarz va hamyon",'Test-keyslar'!$N$2:$N$167,"Avtomatlashtirilgan") | J33: =IF(B33=0,0,I33/B33) | K33: =COUNTIFS('Test-keyslar'!$B$2:$B$167,"Qarz va hamyon",'Test-keyslar'!$P$2:$P$167,"Passed") | L33: =COUNTIFS('Test-keyslar'!$B$2:$B$167,"Qarz va hamyon",'Test-keyslar'!$P$2:$P$167,"Failed") | M33: =COUNTIFS('Test-keyslar'!$B$2:$B$167,"Qarz va hamyon",'Test-keyslar'!$P$2:$P$167,"Blocked") | N33: =COUNTIFS('Test-keyslar'!$B$2:$B$167,"Qarz va hamyon",'Test-keyslar'!$P$2:$P$167,"Skipped") | O33: =COUNTIFS('Test-keyslar'!$B$2:$B$167,"Qarz va hamyon",'Test-keyslar'!$P$2:$P$167,"Bajarilmagan")
A34: MSG — Xabarlar (push, chat) | B34: =COUNTIF('Test-keyslar'!$B$2:$B$167,"Xabarlar (push, chat)") | C34: =COUNTIFS('Test-keyslar'!$B$2:$B$167,"Xabarlar (push, chat)",'Test-keyslar'!$E$2:$E$167,"P1") | D34: =COUNTIFS('Test-keyslar'!$B$2:$B$167,"Xabarlar (push, chat)",'Test-keyslar'!$E$2:$E$167,"P2") | E34: =COUNTIFS('Test-keyslar'!$B$2:$B$167,"Xabarlar (push, chat)",'Test-keyslar'!$E$2:$E$167,"P3") | F34: =COUNTIFS('Test-keyslar'!$B$2:$B$167,"Xabarlar (push, chat)",'Test-keyslar'!$L$2:$L$167,"Ha") | G34: =COUNTIFS('Test-keyslar'!$B$2:$B$167,"Xabarlar (push, chat)",'Test-keyslar'!$L$2:$L$167,"Qisman") | H34: =COUNTIFS('Test-keyslar'!$B$2:$B$167,"Xabarlar (push, chat)",'Test-keyslar'!$L$2:$L$167,"Yo'q") | I34: =COUNTIFS('Test-keyslar'!$B$2:$B$167,"Xabarlar (push, chat)",'Test-keyslar'!$N$2:$N$167,"Avtomatlashtirilgan") | J34: =IF(B34=0,0,I34/B34) | K34: =COUNTIFS('Test-keyslar'!$B$2:$B$167,"Xabarlar (push, chat)",'Test-keyslar'!$P$2:$P$167,"Passed") | L34: =COUNTIFS('Test-keyslar'!$B$2:$B$167,"Xabarlar (push, chat)",'Test-keyslar'!$P$2:$P$167,"Failed") | M34: =COUNTIFS('Test-keyslar'!$B$2:$B$167,"Xabarlar (push, chat)",'Test-keyslar'!$P$2:$P$167,"Blocked") | N34: =COUNTIFS('Test-keyslar'!$B$2:$B$167,"Xabarlar (push, chat)",'Test-keyslar'!$P$2:$P$167,"Skipped") | O34: =COUNTIFS('Test-keyslar'!$B$2:$B$167,"Xabarlar (push, chat)",'Test-keyslar'!$P$2:$P$167,"Bajarilmagan")
A35: PERM — Ruxsatlar | B35: =COUNTIF('Test-keyslar'!$B$2:$B$167,"Ruxsatlar") | C35: =COUNTIFS('Test-keyslar'!$B$2:$B$167,"Ruxsatlar",'Test-keyslar'!$E$2:$E$167,"P1") | D35: =COUNTIFS('Test-keyslar'!$B$2:$B$167,"Ruxsatlar",'Test-keyslar'!$E$2:$E$167,"P2") | E35: =COUNTIFS('Test-keyslar'!$B$2:$B$167,"Ruxsatlar",'Test-keyslar'!$E$2:$E$167,"P3") | F35: =COUNTIFS('Test-keyslar'!$B$2:$B$167,"Ruxsatlar",'Test-keyslar'!$L$2:$L$167,"Ha") | G35: =COUNTIFS('Test-keyslar'!$B$2:$B$167,"Ruxsatlar",'Test-keyslar'!$L$2:$L$167,"Qisman") | H35: =COUNTIFS('Test-keyslar'!$B$2:$B$167,"Ruxsatlar",'Test-keyslar'!$L$2:$L$167,"Yo'q") | I35: =COUNTIFS('Test-keyslar'!$B$2:$B$167,"Ruxsatlar",'Test-keyslar'!$N$2:$N$167,"Avtomatlashtirilgan") | J35: =IF(B35=0,0,I35/B35) | K35: =COUNTIFS('Test-keyslar'!$B$2:$B$167,"Ruxsatlar",'Test-keyslar'!$P$2:$P$167,"Passed") | L35: =COUNTIFS('Test-keyslar'!$B$2:$B$167,"Ruxsatlar",'Test-keyslar'!$P$2:$P$167,"Failed") | M35: =COUNTIFS('Test-keyslar'!$B$2:$B$167,"Ruxsatlar",'Test-keyslar'!$P$2:$P$167,"Blocked") | N35: =COUNTIFS('Test-keyslar'!$B$2:$B$167,"Ruxsatlar",'Test-keyslar'!$P$2:$P$167,"Skipped") | O35: =COUNTIFS('Test-keyslar'!$B$2:$B$167,"Ruxsatlar",'Test-keyslar'!$P$2:$P$167,"Bajarilmagan")
A36: REP — Hisobotlar | B36: =COUNTIF('Test-keyslar'!$B$2:$B$167,"Hisobotlar") | C36: =COUNTIFS('Test-keyslar'!$B$2:$B$167,"Hisobotlar",'Test-keyslar'!$E$2:$E$167,"P1") | D36: =COUNTIFS('Test-keyslar'!$B$2:$B$167,"Hisobotlar",'Test-keyslar'!$E$2:$E$167,"P2") | E36: =COUNTIFS('Test-keyslar'!$B$2:$B$167,"Hisobotlar",'Test-keyslar'!$E$2:$E$167,"P3") | F36: =COUNTIFS('Test-keyslar'!$B$2:$B$167,"Hisobotlar",'Test-keyslar'!$L$2:$L$167,"Ha") | G36: =COUNTIFS('Test-keyslar'!$B$2:$B$167,"Hisobotlar",'Test-keyslar'!$L$2:$L$167,"Qisman") | H36: =COUNTIFS('Test-keyslar'!$B$2:$B$167,"Hisobotlar",'Test-keyslar'!$L$2:$L$167,"Yo'q") | I36: =COUNTIFS('Test-keyslar'!$B$2:$B$167,"Hisobotlar",'Test-keyslar'!$N$2:$N$167,"Avtomatlashtirilgan") | J36: =IF(B36=0,0,I36/B36) | K36: =COUNTIFS('Test-keyslar'!$B$2:$B$167,"Hisobotlar",'Test-keyslar'!$P$2:$P$167,"Passed") | L36: =COUNTIFS('Test-keyslar'!$B$2:$B$167,"Hisobotlar",'Test-keyslar'!$P$2:$P$167,"Failed") | M36: =COUNTIFS('Test-keyslar'!$B$2:$B$167,"Hisobotlar",'Test-keyslar'!$P$2:$P$167,"Blocked") | N36: =COUNTIFS('Test-keyslar'!$B$2:$B$167,"Hisobotlar",'Test-keyslar'!$P$2:$P$167,"Skipped") | O36: =COUNTIFS('Test-keyslar'!$B$2:$B$167,"Hisobotlar",'Test-keyslar'!$P$2:$P$167,"Bajarilmagan")
A37: E2E — Admin ↔ vitrina stsenariylari | B37: =COUNTIF('Test-keyslar'!$B$2:$B$167,"Admin ↔ vitrina stsenariylari") | C37: =COUNTIFS('Test-keyslar'!$B$2:$B$167,"Admin ↔ vitrina stsenariylari",'Test-keyslar'!$E$2:$E$167,"P1") | D37: =COUNTIFS('Test-keyslar'!$B$2:$B$167,"Admin ↔ vitrina stsenariylari",'Test-keyslar'!$E$2:$E$167,"P2") | E37: =COUNTIFS('Test-keyslar'!$B$2:$B$167,"Admin ↔ vitrina stsenariylari",'Test-keyslar'!$E$2:$E$167,"P3") | F37: =COUNTIFS('Test-keyslar'!$B$2:$B$167,"Admin ↔ vitrina stsenariylari",'Test-keyslar'!$L$2:$L$167,"Ha") | G37: =COUNTIFS('Test-keyslar'!$B$2:$B$167,"Admin ↔ vitrina stsenariylari",'Test-keyslar'!$L$2:$L$167,"Qisman") | H37: =COUNTIFS('Test-keyslar'!$B$2:$B$167,"Admin ↔ vitrina stsenariylari",'Test-keyslar'!$L$2:$L$167,"Yo'q") | I37: =COUNTIFS('Test-keyslar'!$B$2:$B$167,"Admin ↔ vitrina stsenariylari",'Test-keyslar'!$N$2:$N$167,"Avtomatlashtirilgan") | J37: =IF(B37=0,0,I37/B37) | K37: =COUNTIFS('Test-keyslar'!$B$2:$B$167,"Admin ↔ vitrina stsenariylari",'Test-keyslar'!$P$2:$P$167,"Passed") | L37: =COUNTIFS('Test-keyslar'!$B$2:$B$167,"Admin ↔ vitrina stsenariylari",'Test-keyslar'!$P$2:$P$167,"Failed") | M37: =COUNTIFS('Test-keyslar'!$B$2:$B$167,"Admin ↔ vitrina stsenariylari",'Test-keyslar'!$P$2:$P$167,"Blocked") | N37: =COUNTIFS('Test-keyslar'!$B$2:$B$167,"Admin ↔ vitrina stsenariylari",'Test-keyslar'!$P$2:$P$167,"Skipped") | O37: =COUNTIFS('Test-keyslar'!$B$2:$B$167,"Admin ↔ vitrina stsenariylari",'Test-keyslar'!$P$2:$P$167,"Bajarilmagan")
A38: GEN — Interfeysning umumiy tekshiruvlari | B38: =COUNTIF('Test-keyslar'!$B$2:$B$167,"Interfeysning umumiy tekshiruvlari") | C38: =COUNTIFS('Test-keyslar'!$B$2:$B$167,"Interfeysning umumiy tekshiruvlari",'Test-keyslar'!$E$2:$E$167,"P1") | D38: =COUNTIFS('Test-keyslar'!$B$2:$B$167,"Interfeysning umumiy tekshiruvlari",'Test-keyslar'!$E$2:$E$167,"P2") | E38: =COUNTIFS('Test-keyslar'!$B$2:$B$167,"Interfeysning umumiy tekshiruvlari",'Test-keyslar'!$E$2:$E$167,"P3") | F38: =COUNTIFS('Test-keyslar'!$B$2:$B$167,"Interfeysning umumiy tekshiruvlari",'Test-keyslar'!$L$2:$L$167,"Ha") | G38: =COUNTIFS('Test-keyslar'!$B$2:$B$167,"Interfeysning umumiy tekshiruvlari",'Test-keyslar'!$L$2:$L$167,"Qisman") | H38: =COUNTIFS('Test-keyslar'!$B$2:$B$167,"Interfeysning umumiy tekshiruvlari",'Test-keyslar'!$L$2:$L$167,"Yo'q") | I38: =COUNTIFS('Test-keyslar'!$B$2:$B$167,"Interfeysning umumiy tekshiruvlari",'Test-keyslar'!$N$2:$N$167,"Avtomatlashtirilgan") | J38: =IF(B38=0,0,I38/B38) | K38: =COUNTIFS('Test-keyslar'!$B$2:$B$167,"Interfeysning umumiy tekshiruvlari",'Test-keyslar'!$P$2:$P$167,"Passed") | L38: =COUNTIFS('Test-keyslar'!$B$2:$B$167,"Interfeysning umumiy tekshiruvlari",'Test-keyslar'!$P$2:$P$167,"Failed") | M38: =COUNTIFS('Test-keyslar'!$B$2:$B$167,"Interfeysning umumiy tekshiruvlari",'Test-keyslar'!$P$2:$P$167,"Blocked") | N38: =COUNTIFS('Test-keyslar'!$B$2:$B$167,"Interfeysning umumiy tekshiruvlari",'Test-keyslar'!$P$2:$P$167,"Skipped") | O38: =COUNTIFS('Test-keyslar'!$B$2:$B$167,"Interfeysning umumiy tekshiruvlari",'Test-keyslar'!$P$2:$P$167,"Bajarilmagan")
A39: JAMI | B39: =SUM(B14:B38) | C39: =SUM(C14:C38) | D39: =SUM(D14:D38) | E39: =SUM(E14:E38) | F39: =SUM(F14:F38) | G39: =SUM(G14:G38) | H39: =SUM(H14:H38) | I39: =SUM(I14:I38) | J39: =IF(B39=0,0,I39/B39) | K39: =SUM(K14:K38) | L39: =SUM(L14:L38) | M39: =SUM(M14:M38) | N39: =SUM(N14:N38) | O39: =SUM(O14:O38)
A41: Izohlar
A42: P1 — kritik | B42: Relizni bloklaydi. Smoke-to'plam: har doim bajariladi.
...

Sheet Test-keyslar
A1: ID | B1: Modul | C1: Submodul | D1: Test-keys nomi | E1: Ustuvorlik | F1: Turi | G1: Dastlabki shartlar | H1: Qadamlar | I1: Test ma'lumotlari | J1: Kutilgan natija | K1: Talab / manba | L1: Avtomatlashtirish mumkinmi (UI) | M1: Avtomatlashtirish bo'yicha izoh | N1: UI-avtomatlashtirish holati | O1: Avtotest (klass#metod) | P1: Progon natijasi | Q1: Izoh / bagga havola
A2: AUTH-001 | B2: Avtorizatsiya va ruxsat | C2: Kirish | D2: Admin panelga muvaffaqiyatli kirish | E2: P1 | F2: Smoke | G2: Foydalanuvchi tizimga kirmagan | H2: 1. https://staging-admin.aros.uz ni ochish 2. Username va parolni kiritish 3. «Login»ni bosish | I2: +998998987882 / <пароль в .env> | J2: Bosh sahifa ochiladi, yuqorida foydalanuvchi avatari, «Successfully completed» xabari | K2: Staging admin panel, 28.10.2026 | L2: Ha | M2: .env da ADMIN_USERNAME/ADMIN_PASSWORD bo'lmasa test o'tkazib yuboriladi | N2: Avtomatlashtirilgan | O2: admin/AdminLoginTest#successfulLogin | P2: Bajarilmagan
A3: AUTH-002 | B3: Avtorizatsiya va ruxsat | C3: Kirish | D3: Noto'g'ri parol bilan kirish | E3: P1 | F3: Negative | G3: Foydalanuvchi tizimga kirmagan | H3: 1. To'g'ri username va noto'g'ri parol kiritish 2. «Login» | J3: Avtorizatsiya xatosi, kirish formasi qoladi, sahifalarga kirish yo'q | L3: Ha | M3: .env da ADMIN_* kerak | N3: Avtomatlashtirilgan | O3: admin/AdminLoginTest#loginFailsWithWrongPassword | P3: Bajarilmagan
A4: AUTH-003 | B4: Avtorizatsiya va ruxsat | C4: Kirish | D4: Bo'sh maydonlar bilan kirish | E4: P2 | F4: Negative | G4: Foydalanuvchi tizimga kirmagan | H4: 1. Bo'sh maydonlar bilan «Login»ni bosish 2. Faqat username ni to'ldirish | J4: Majburiy maydonlar validatsiyasi, so'rov yuborilmaydi | L4: Ha | N4: Avtomatlashtirilmagan | P4: Bajarilmagan
A5: AUTH-004 | B5: Avtorizatsiya va ruxsat | C5: Kirish | D5: Parolni yashirish | E5: P3 | F5: UI | G5: Kirish sahifasi ochiq | H5: 1. Parol kiritish 2. Ko'z belgisini bosish | J5: Parol odatda yashirin; belgi uni ko'rsatadi/yashiradi | L5: Ha | N5: Avtomatlashtirilmagan | P5: Bajarilmagan
A6: AUTH-005 | B6: Avtorizatsiya va ruxsat | C6: Kirish | D6: «Forgot password?» | E6: P3 | F6: Functional | G6: Kirish sahifasi ochiq | H6: 1. «Forgot password?»ni bosish | J6: /forgot-password ochiladi, tiklash formasi ishlaydi | L6: Qisman | M6: SMS/OTP ga bog'liq | N6: Avtomatlashtirilmagan | P6: Bajarilmagan
A7: AUTH-006 | B7: Avtorizatsiya va ruxsat | C7: Sessiya | D7: Avtorizatsiyasiz to'g'ridan-to'g'ri URL | E7: P1 | F7: Security | G7: Foydalanuvchi tizimga kirmagan | H7: 1. /orders/orders-list, /users/user ni to'g'ridan-to'g'ri ochish | J7: /sign-in ga yo'naltiriladi, ma'lumotlar ko'rinmaydi | L7: Ha | N7: Avtomatlashtirilmagan | P7: Bajarilmagan
A8: AUTH-007 | B8: Avtorizatsiya va ruxsat | C8: Sessiya | D8: Sahifa yangilanganda sessiya saqlanadi | E8: P2 | F8: Functional | G8: Admin panelga test akkaunti bilan kirilgan (to'liq huquqlar) | H8: 1. Sahifani yangilash 2. Yangi tabda ochish | J8: Foydalanuvchi tizimda qoladi | L8: Ha | N8: Avtomatlashtirilmagan | P8: Bajarilmagan
A9: AUTH-008 | B9: Avtorizatsiya va ruxsat | C9: Sessiya | D9: Admin paneldan chiqish | E9: P1 | F9: Smoke | G9: Admin panelga test akkaunti bilan kirilgan (to'liq huquqlar) | H9: 1. Avatar menyusi → Logout | J9: Sessiya tugaydi, /sign-in ga yo'naltiriladi; brauzerda «Orqaga» ma'lumotlarni ochmaydi | L9: Ha | N9: Avtomatlashtirilmagan | P9: Bajarilmagan
A10: AUTH-009 | B10: Avtorizatsiya va ruxsat | C10: Ruxsat | D10: Admin panelga ruxsati yo'q foydalanuvchi (mijoz) | E10: P2 | F10: Security | G10: Xodim roli yo'q mijoz akkaunti | H10: 1. Admin panelga mijoz akkaunti bilan kirish | J10: Kirish taqiqlanadi yoki birorta modul ko'rinmaydi | L10: Qisman | M10: Huquqsiz akkaunt kerak | N10: Avtomatlashtirilmagan | P10: Bajarilmagan
A11: DASH-001 | B11: Bosh sahifa (Dashboard) | C11: Filial limiti | D11: «Filial qarz limiti» bloki | E11: P2 | F11: Functional | G11: Admin panelga test akkaunti bilan kirilgan (to'liq huquqlar) | H11: 1. Bosh sahifani ochish 2. Filial tablarini almashtirish | J11: Kartalar: umumiy limit, limitli filiallar qarzi, limitdan oshganlar, limitga yaqin (80–100%), limitsiz filiallar; filial bo'yicha: limit, joriy qarz, qolgan, bandlik %; «Ro'yxatga o'tish» → /debt/warehouse-debt-limits | K11: PRD Filial qarz limiti | L11: Ha | N11: Avtomatlashtirilmagan | P11: Bajarilmagan
A12: DASH-002 | B12: Bosh sahifa (Dashboard) | C12: Kassa | D12: «Kassa hisoboti» bloki: tablar va «Yangilash» | E12: P2 | F12: Functional | G12: Admin panelga test akkaunti bilan kirilgan (to'liq huquqlar) | H12: 1. Ombor tabini tanlash 2. «Yangilash»ni bosish | J12: Faqat tanlangan ombor hisoblanadi; ma'lumot faqat «Yangilash» bosilganda qayta hisoblanadi; xato bo'lsa eski holat xabar bilan qoladi; vaqt yangilanadi | K12: PRD Bosh sahifa — Kassa bloki | L12: Qisman | M12: Summalarni kassa hisoboti bilan solishtirish | N12: Avtomatlashtirilmagan | P12: Bajarilmagan
A13: DASH-003 | B13: Bosh sahifa (Dashboard) | C13: Reyting | D13: Omborlar reytingi bloki | E13: P3 | F13: UI | G13: Admin panelga test akkaunti bilan kirilgan (to'liq huquqlar) | H13: 1. Bosh sahifani pastga aylantirish 2. «Barchasi»ni bosish | J13: Blok ko'rinadi; «Barchasi» → /warehouse/warehouse-rating | L13: Ha | N13: Avtomatlashtirilmagan | P13: Bajarilmagan
A14: DASH-004 | B14: Bosh sahifa (Dashboard) | C14: Ruxsat | D14: Bosh sahifadagi omborlar foydalanuvchi huquqiga qarab | E14: P2 | F14: Security | G14: Foydalanuvchi — bitta ombor sotuvchisi | H14: 1. Bosh sahifani ochish | J14: Faqat o'z omborining tabi ko'rinadi | L14: Qisman | M14: Sotuvchi akkaunti kerak | N14: Avtomatlashtirilmagan | P14: Bajarilmagan
A15: PINC-001 | B15: Qabul qilingan mahsulot (kirim) | C15: Ro'yxat | D15: Kirimlar ro'yxati va filtrlari | E15: P2 | F15: Functional | G15: Admin panelga test akkaunti bilan kirilgan (to'liq huquqlar) | H15: 1. Mahsulotlar amallari → Qabul qilingan mahsulot 2. Filtr: sana oralig'i, ombor, yetkazib beruvchi, status, yetkazish holati | J15: Ro'yxat filtrlanadi; ustunlar: ID, yaratilgan sana, ombor, yetkazib beruvchi, narx, status, yetkazish holati, nashr statusi, nashr qilingan vaqti; sahifalash ishlaydi | L15: Ha | N15: Avtomatlashtirilmagan | P15: Bajarilmagan
A16: PINC-002 | B16: Qabul qilingan mahsulot (kirim) | C16: Yaratish | D16: Kirim hujjatini yaratish | E16: P1 | F16: Smoke | G16: Admin panelga test akkaunti bilan kirilgan (to'liq huquqlar) | H16: 1. «Yaratish» 2. Ombor, yetkazib beruvchi, yetkazish holati, yetkazish sanasi, valyutani tanlash 3. «Add» — variant, miqdor, kirim narxini qo'shish 4. «Saqlash» | I16: Ombor: Asosiy ombor; yetkazib beruvchi — istalgan | J16: Hujjat «Yaratilgan» statusida; qatorga oxirgi kirim narxi, o'rtacha narx, B2B/B2M/B2C narxlari tortiladi | L16: Ha | N16: Avtomatlashtirilmagan | P16: Bajarilmagan
A17: PINC-003 | B17: Qabul qilingan mahsulot (kirim) | C17: Narxlar | D17: O'rtacha narx va ustama hisobi | E17: P1 | F17: Functional | G17: Admin panelga test akkaunti bilan kirilgan (to'liq huquqlar); kirim hujjati ochiq | H17: 1. Kirim narxi, Fare percent, Custom clearance kiritish 2. «Fill income price» / «Apply»ni bosish | J17: O'rtacha narx qayta hisoblanadi; B2B/B2M/B2C narxlari ≥ 1 va [o'rtacha narx; o'rtacha × (1 + Max margin %)] oralig'ida | K17: PRD Product Income Excel Import | L17: Qisman | M17: Formulani calculate-average-prices API orqali solishtirish | N17: Avtomatlashtirilmagan | P17: Bajarilmagan
A18: PINC-004 | B18: Qabul qilingan mahsulot (kirim) | C18: Narxlar | D18: Ruxsat etilgan oraliqdan tashqari sotuv narxi | E18: P1 | F18: Negative | G18: Admin panelga test akkaunti bilan kirilgan (to'liq huquqlar); kirim hujjati ochiq | H18: 1. B2C narxini o'rtacha narxdan past qo'yish 2. «Saqlash» | J18: Saqlash bloklanadi, qatorda xato | L18: Ha | N18: Avtomatlashtirilmagan | P18: Bajarilmagan
A19: PINC-005 | B19: Qabul qilingan mahsulot (kirim) | C19: Excel | D19: Yetkazib beruvchi Excel faylidan qatorlarni import qilish | E19: P2 | F19: Functional | G19: Admin panelga test akkaunti bilan kirilgan (to'liq huquqlar); yangi kirim hujjati ochiq | H19: 1. «Template» — shablonni yuklab olish 2. Variant, miqdor, narxni to'ldirish 3. «Import» | J19: Qatorlar avtomatik to'ldiriladi va darhol saqlashga yaroqli; hosila narxlar tortiladi | K19: PRD Product Income Excel Import | L19: Ha | N19: Avtomatlashtirilmagan | P19: Bajarilmagan
A20: PINC-006 | B20: Qabul qilingan mahsulot (kirim) | C20: Excel | D20: Xatoli Excel import | E20: P2 | F20: Negative | G20: Admin panelga test akkaunti bilan kirilgan (to'liq huquqlar) | H20: 1. Mavjud bo'lmagan variant / bo'sh miqdorli fayl import qilish | J20: Import butunlay rad etiladi (hammasi yoki hech narsa), qator/ustun raqami bilan tushunarli o'zbekcha xato | L20: Ha | N20: Avtomatlashtirilmagan | P20: Bajarilmagan
A21: PINC-007 | B21: Qabul qilingan mahsulot (kirim) | C21: Statuslar | D21: «Yo'lda» → «Qabul qilingan» → «Nashr» | E21: P1 | F21: Smoke | G21: Admin panelga test akkaunti bilan kirilgan (to'liq huquqlar); kirim hujjati «Yaratilgan», yetkazish «Yo'lda» | H21: 1. Yetkazish holatini «Qabul qilingan»ga o'zgartirish 2. Saqlash 3. «Nashr» | J21: Nashr faqat «Qabul qilingan»da mumkin; nashrdan keyin ombor qoldig'i miqdorga oshadi; nashr vaqti to'ldiriladi; hujjat tahrirlash uchun qulflanadi (faqat izoh) | K21: PRD Kirim — qisman kelish | L21: Ha | N21: Avtomatlashtirilmagan | P21: Bajarilmagan
A22: PINC-008 | B22: Qabul qilingan mahsulot (kirim) | C22: Statuslar | D22: Qabul qilinmaguncha nashr qilib bo'lmaydi | E22: P2 | F22: Negative | G22: Admin panelga test akkaunti bilan kirilgan (to'liq huquqlar); hujjat «Yo'lda» | H22: 1. «Nashr»ga urinish | J22: Tugma faol emas / xato | L22: Ha | N22: Avtomatlashtirilmagan | P22: Bajarilmagan
A23: PINC-009 | B23: Qabul qilingan mahsulot (kirim) | C23: Qisman qabul | D23: Qisman kelish («Keldi») | E23: P2 | F23: Functional | G23: Admin panelga test akkaunti bilan kirilgan (to'liq huquqlar); hujjat «Yaratilgan» + «Yo'lda» | H23: 1. Qatorlarni belgilash 2. «Keldi», kelgan miqdorni kiritish (1…hujjatdagi miqdor) 3. «Qabul qilish» | J23: Kelgan miqdor bilan «Qabul qilingan» yangi hujjat yaratiladi; asl hujjatda faqat kelmaganlar qoladi; yig'indilar mos; oraliqdan tashqari — xato, tugma faol emas | K23: PRD Kirim — qisman kelish (AIDT-753) | L23: Ha | N23: Avtomatlashtirilmagan | P23: Bajarilmagan
A24: PINC-010 | B24: Qabul qilingan mahsulot (kirim) | C24: Chop etish | D24: Yorliq chop etish (Label / Yorliq nomi) | E24: P3 | F24: Functional | G24: Admin panelga test akkaunti bilan kirilgan (to'liq huquqlar); mahsulotli kirim hujjati | H24: 1. Qatordagi «Label» / «Print»ni bosish | J24: Yorliq nomi bilan yorliq chop etish oynasi ochiladi | L24: Qisman | M24: Chop etish vizual tekshiriladi | N24: Avtomatlashtirilmagan | P24: Bajarilmagan
A25: PINC-011 | B25: Qabul qilingan mahsulot (kirim) | C25: Bog'liqlik | D25: Kirim «Bo'lsa olar edim» so'rovlarini yopadi | E25: P2 | F25: Integration | G25: Qoldig'i yo'q variantga «Bo'lsa olar edim» so'rovi bor | H25: 1. Shu variant kirimini mijoz omboriga nashr qilish 2. So'rovlar → Bo'lsa olar edim ni ochish | J25: So'rov «Tugallangan», sana, ijrochi va kirim ko'rsatilgan | K25: PRD Bo'lsa olar edim (admin) | L25: Ha | N25: Avtomatlashtirilmagan | P25: Bajarilmagan
A26: PRICE-001 | B26: Narxni o'zgartirish | C26: Hujjat | D26: Narxni o'zgartirish hujjatini yaratish | E26: P1 | F26: Smoke | G26: Admin panelga test akkaunti bilan kirilgan (to'liq huquqlar) | H26: 1. Mahsulotlar amallari → Narxni o'zgartirish → «Yaratish» 2. «Add» variant 3. Yangi B2B/B2C/B2M narxlarini kiritish 4. «Saqlash» | J26: Hujjat saqlanadi; uchta tur bo'yicha eski va yangi narxlar ko'rinadi | L26: Ha | N26: Avtomatlashtirilmagan | P26: Bajarilmagan
A27: PRICE-002 | B27: Narxni o'zgartirish | C27: Nashr | D27: Nashr vitrinadagi narxlarni yangilaydi | E27: P1 | F27: Integration | G27: Admin panelga test akkaunti bilan kirilgan (to'liq huquqlar); narx hujjati saqlangan | H27: 1. «Nashr» 2. Vitrinada mahsulotni mijoz va usta sifatida ochish | J27: Nashr sanasi to'ldiriladi; vitrinada yangi B2C (mijoz) va B2M (usta) narxlari | L27: Ha | N27: Avtomatlashtirilmagan | P27: Bajarilmagan
A28: PRICE-003 | B28: Narxni o'zgartirish | C28: Validatsiya | D28: Bo'sh yoki nol yangi narx | E28: P2 | F28: Negative | G28: Admin panelga test akkaunti bilan kirilgan (to'liq huquqlar) | H28: 1. Yangi narxni bo'sh yoki 0 qoldirish 2. «Saqlash» | J28: Saqlash xato bilan bloklanadi | L28: Ha | N28: Avtomatlashtirilmagan | P28: Bajarilmagan
A29: PRICE-004 | B29: Narxni o'zgartirish | C29: Ro'yxat | D29: Narx hujjatlari ro'yxati | E29: P3 | F29: UI | G29: Admin panelga test akkaunti bilan kirilgan (to'liq huquqlar) | H29: 1. Narxni o'zgartirish ni ochish 2. Qidiruv, sahifalash | J29: Ustunlar: Id, yaratilgan sana, nashr sanasi; sahifalash ishlaydi | L29: Ha | N29: Avtomatlashtirilmagan | P29: Bajarilmagan
A30: INV-001 | B30: Inventarizatsiya | C30: Yaratish | D30: Inventarizatsiyani boshlash | E30: P1 | F30: Smoke | G30: Admin panelga test akkaunti bilan kirilgan (to'liq huquqlar); omborda faol inventarizatsiya yo'q | H30: 1. Mahsulotlar amallari → Inventorizatsiya → «Yaratish» 2. Ombor, tur (Offline/Online) 3. «Start» | J30: Hujjat yaratiladi; ombor brak ombori bilan birga inventarizatsiya rejimida (muzlatilgan) | L30: Ha | N30: Avtomatlashtirilmagan | P30: Bajarilmagan
A31: INV-002 | B31: Inventarizatsiya | C31: Cheklovlar | D31: Bitta omborda ikkinchi inventarizatsiya | E31: P1 | F31: Negative | G31: Admin panelga test akkaunti bilan kirilgan (to'liq huquqlar); omborda faol inventarizatsiya bor | H31: 1. Shu omborga yana bittasini boshlash | J31: Xato bilan bloklanadi; boshqa omborda boshlash mumkin | K31: PRD Inventory | L31: Ha | N31: Avtomatlashtirilmagan | P31: Bajarilmagan
A32: INV-003 | B32: Inventarizatsiya | C32: Cheklovlar | D32: Inventarizatsiya vaqtida ombor amallari | E32: P1 | F32: Negative | G32: Admin panelga test akkaunti bilan kirilgan (to'liq huquqlar); ombor inventarizatsiya rejimida | H32: 1. Shu omborga o'tkazma yuborish / kirimni nashr qilishga urinish | J32: Amallar tushunarli xato bilan bloklanadi | L32: Qisman | N32: Avtomatlashtirilmagan | P32: Bajarilmagan
A33: INV-004 | B33: Inventarizatsiya | C33: Ochiq hujjatlar | D33: Boshlashdan oldin ochiq hujjatlar oynasi | E33: P2 | F33: Functional | G33: Admin panelga test akkaunti bilan kirilgan (to'liq huquqlar); omborda «Yaratilgan/Tayyorlandi/Yo'lda/Qaytarilgan» o'tkazmalar bor | H33: 1. Inventarizatsiyani boshlash | J33: Ochiq hujjatlar oynasi ko'rsatiladi; qaytarilganlar bloklamaydi | L33: Qisman | N33: Avtomatlashtirilmagan | P33: Bajarilmagan
A34: INV-005 | B34: Inventarizatsiya | C34: Excel | D34: Excelni yuklab olish va yuklash | E34: P1 | F34: Functional | G34: Admin panelga test akkaunti bilan kirilgan (to'liq huquqlar); faol inventarizatsiya | H34: 1. «Yuklab olish» 2. Faktni to'ldirish 3. Faylni yuklash | J34: Excelda qoldiqlar va harakat ustunlari bor (Transfer Yaratilgan / Tayyorlandi / Yo'lda / Transfer return); yuklash ma'lumotlarni tekshiradi | L34: Ha | N34: Avtomatlashtirilmagan | P34: Bajarilmagan
A35: INV-006 | B35: Inventarizatsiya | C35: Excel | D35: Noto'g'ri faylni yuklash | E35: P2 | F35: Negative | G35: Admin panelga test akkaunti bilan kirilgan (to'liq huquqlar) | H35: 1. Boshqa ombor fayli / miqdorda harf bor faylni yuklash | J35: Validatsiya xatosi, ma'lumotlar o'zgarmaydi | L35: Ha | N35: Avtomatlashtirilmagan | P35: Bajarilmagan
A36: INV-007 | B36: Inventarizatsiya | C36: Online | D36: Online inventarizatsiya: bo'sh qatorlar o'tkazib yuboriladi | E36: P2 | F36: Functional | G36: Admin panelga test akkaunti bilan kirilgan (to'liq huquqlar) | H36: 1. Tur — Online 2. Faktni faqat 2 qatorda to'ldirish 3. Nashr qilish | J36: Faqat to'ldirilgan qatorlar o'zgaradi; bo'shlarida harakat yo'q | L36: Ha | N36: Avtomatlashtirilmagan | P36: Bajarilmagan
A37: INV-008 | B37: Inventarizatsiya | C37: Nashr | D37: Inventarizatsiyani nashr qilish | E37: P1 | F37: Functional | G37: Admin panelga test akkaunti bilan kirilgan (to'liq huquqlar); fayl yuklangan | H37: 1. Nashr qilish | J37: Qoldiqlar = fakt; harakat tarixi yoziladi; ombor muzlatishdan chiqadi; status «Nashr qilingan» | L37: Ha | N37: Avtomatlashtirilmagan | P37: Bajarilmagan
A38: TRF-001 | B38: Mahsulot yuborish (o'tkazma) | C38: Ro'yxat | D38: O'tkazmalar ro'yxati va tablar | E38: P2 | F38: Functional | G38: Admin panelga test akkaunti bilan kirilgan (to'liq huquqlar) | H38: 1. Mahsulotlar amallari → Mahsulot yuborish 2. Tablar: Hammasi / O'tkazma / So'rov | J38: Ustunlar: ID, turi, yaratilgan sana, qaysi ombordan, qaysi omborga, narx, jo'natilgan, qabul qilingan sana, izoh, holat; tablar tur bo'yicha filtrlaydi | L38: Ha | N38: Avtomatlashtirilmagan | P38: Bajarilmagan
A39: TRF-002 | B39: Mahsulot yuborish (o'tkazma) | C39: O'tkazma | D39: O'tkazma yaratish | E39: P1 | F39: Smoke | G39: Admin panelga test akkaunti bilan kirilgan (to'liq huquqlar) | H39: 1. O'tkazma yaratish: jo'natuvchi (o'z ombori), qabul qiluvchi, mahsulotlar va miqdor 2. Saqlash | J39: Status «Yaratilgan»; jo'natuvchi qoldig'i band qilinadi (bo'sh qoldiq + hujjat bandi ko'rsatiladi) | K39: PRD Product Transfer | L39: Ha | N39: Avtomatlashtirilmagan | P39: Bajarilmagan
A40: TRF-003 | B40: Mahsulot yuborish (o'tkazma) | C40: O'tkazma | D40: Jo'natish va qabul qilish | E40: P1 | F40: Smoke | G40: O'tkazma «Yaratilgan» | H40: 1. Jo'natuvchi: «Jo'natish» 2. Qabul qiluvchi: «Qabul qilish» | J40: «Yo'lda» → «Qabul qilingan»; mahsulot jo'natuvchidan chiqariladi va qabul qiluvchiga qo'shiladi; jo'natish/qabul sanalari to'ldiriladi | L40: Ha | N40: Avtomatlashtirilmagan | P40: Bajarilmagan
...

Sheet Kamchiliklar
A1: № | B1: Kategoriya | C1: Tavsif | D1: Qayerda | E1: Jiddiylik | F1: Izoh | G1: Holat
A2: 1 | B2: Ma'lumot | C2: «Qarz cheklovi»da oddiy B2C mijozlarga ham limit qo'yilgan (B2C, 300 000 000) | D2: /debt/debt-limit | E2: Medium | F2: PRD Mijoz rollari §6.7 da ham nosozlik deb ko'rsatilgan — tasdiqlash kerak | G2: Yangi
A3: 2 | B3: Mantiq | C3: Bloklangan hamyon Hamyon bilan to'lovga to'sqinlik qilmaydi | D3: Checkout / Qarz cheklovi | E3: High | F3: PRD Debt Limit dagi kod tekshiruvi izohidan — staging da tekshirish kerak | G3: Yangi
A4: 3 | B4: Lokalizatsiya | C4: Hamyon holati «free» / «blocked» ko'rinishida tarjimasiz | D4: Hamyon tranzaksiyalari, Hamyon | E4: Low | F4: PRD Wallet (kod tekshiruvi) | G4: Yangi
A5: 4 | B5: Lokalizatsiya | C5: Omborlar nomlari turli tillarda (masalan «Урикзор Магазин №43»); UZ rejimida ham Kassa hisoboti tablari inglizcha | D5: Bosh sahifa, Mavsum, Kassa hisoboti | E5: Low | F5: 28.10.2026 da UZ tilida tekshirilgan | G5: Yangi
A6: 5 | B6: Ma'lumot | C6: Bekor qilingan #518191 buyurtmada bekor qilish sababi «abc» | D6: /orders/518191 | E6: Info | F6: Matn qayerdan kelishini tekshirish | G6: Yangi
B8: Kamchiliklar staging'ni usta akkaunti bilan o'rganishda topilgan (28.10.2026). Bag ochishdan oldin qayta tekshiring.

Sheet Manbalar
A1: PRD / sahifa | B1: Nima haqida | C1: Havola
A2: Папка логики админки (Confluence) | B2: 1–15 bo'limlar | C2: https://arositdepartment.atlassian.net/wiki/spaces/~ArosMarket/folder/354385922
A3: Admin Order List and Order Detail | B3: Buyurtmalar | C3: https://arositdepartment.atlassian.net/wiki/spaces/~ArosMarket/pages/333774849
A4: Product Transfer / Transfer permission | B4: O'tkazmalar | C4: https://arositdepartment.atlassian.net/wiki/spaces/~ArosMarket/pages/304021505
A5: Inventory PRD | B5: Inventarizatsiya | C5: https://arositdepartment.atlassian.net/wiki/spaces/~ArosMarket/pages/305135617
A6: Product Income — Excel Import | B6: Kirim, Excel import | C6: https://arositdepartment.atlassian.net/wiki/spaces/~ArosMarket/pages/324861953
A7: Kirim — qisman kelish | B7: Qisman qabul | C7: https://arositdepartment.atlassian.net/wiki/spaces/~ArosMarket/pages/376209409
A8: Discount US1 / PRD | B8: Aksiyalar | C8: https://arositdepartment.atlassian.net/wiki/spaces/~ArosMarket/pages/154632194
A9: Mijozga xos chegirma ko'rinishi | B9: Narx turi bo'yicha chegirmalar | C9: https://arositdepartment.atlassian.net/wiki/spaces/~ArosMarket/pages/377651202
A10: Product & Product Variant | B10: Mahsulotlar va variantlar | C10: https://arositdepartment.atlassian.net/wiki/spaces/~ArosMarket/pages/292356097
A11: Sales window - PRD | B11: Sotuv oynasi | C11: https://arositdepartment.atlassian.net/wiki/spaces/~ArosMarket/pages/307167233
A12: Product Return | B12: Qaytarishlar | C12: https://arositdepartment.atlassian.net/wiki/spaces/~ArosMarket/pages/298024961
... A18: Roles and Permissions Module | B18: Ruxsatlar | C18: https://arositdepartment.atlassian.net/wiki/spaces/~ArosMarket/pages/243597313
